Workbook

Sheet Parametros
A1: PARÁMETROS Y SUPUESTOS DEL MODELO
A2: Celdas en AZUL son editables. Ajusta aquí y todo el archivo recalcula.
A4: TIPO DE CAMBIO
A5: TRM (COP por 1 USD) | B5: 3300 | C5: Fuente: tasa de mercado referencial, jul-2026. Ajustar a TRM del día de facturación.
A7: PROYECTO — ALCANCE
A8: Número de referencias (SKUs) | B8: 55
A9: Número de modelos IA a desarrollar | B9: 5
A10: Referencias cubiertas por cada modelo | B10: =Parametros!$B$8/Parametros!$B$9
A12: SUSCRIPCIONES MENSUALES DE HERRAMIENTAS
A13: Claude (USD/mes) | B13: 20
A14: ChatGPT (COP/mes) | B14: 20000
A15: Figma Weave (USD/mes) | B15: 24
A16: % del mes asignado a este proyecto | B16: 1 | C16: Si el mes se reparte entre varios clientes, bajar este %.
A18: MANO DE OBRA / DIRECCIÓN CREATIVA
A19: Horas estimadas del proyecto | B19: 55 | C19: Ver desglose sugerido en hoja 'Horas estimadas'.
A20: Tarifa por hora (COP) | B20: 25000 | C20: Ajusta a tu tarifa real de mercado / experiencia.
A22: CONTINGENCIA POR REGENERACIÓN (fallos / inconsistencias)
A23: % de imágenes a regenerar por referencia | B23: 0.2 | C23: Aplica sobre fichas, imagen base, sets de fotos, upscale y nodos LLM.
A24: % de clips de video a regenerar por referencia | B24: 0.25 | C24: Los clips de video suelen tener mayor tasa de fallos/inconsistencias que la imagen fija.
A26: RENTABILIDAD
A27: Margen de rentabilidad objetivo | B27: 0.6 | C27: Rango estándar de agencia: 50%-70% sobre costo total.
A28: ¿Cotización sujeta a IVA (19%)? | B28: 0 | C28: Poner 19% (0.19) si eres responsable de IVA. Verificar con tu contador/régimen tributario.

Sheet Costeo Generacion IA
A1: COSTEO DE GENERACIÓN IA — DATOS REALES DE CONSUMO
A2: Valores base en USD tomados del consumo reportado por el usuario. Incluye contingencia por regeneración.
A4: A) COSTO POR MODELO IA — se genera 1 sola vez, cubre 10 referencias
A5: Concepto | B5: Herramienta / Modelo IA | C5: Créditos | D5: Valor (USD) | E5: — | F5: Valor (COP)
A6: Identidad de modelo (variantes) | B6: Figma Weave / Nanobanana Pro 2K | C6: 66 | D6: 0.66 | F6: =D6*Parametros!$B$5
A8: B) COSTO POR REFERENCIA — se repite en cada una de las 55 referencias
A9: B.1) Fichas técnicas (identidad + fit — fit es uso interno, no se entrega al cliente)
A10: Concepto | B10: Herramienta / Modelo IA | C10: Créditos | D10: Valor (USD) | E10: — | F10: Valor (COP)
A11: Fichas de identidad de prendas (6 prendas) — SE ENTREGA | B11: KIE / Nanobanana Pro 4K | C11: 144 | D11: 0.72 | F11: =D11*Parametros!$B$5
A12: Fichas de fit de prendas — uso interno, NO se entrega | B12: Figma Weave / Nanobanana Pro 2K | C12: 44 | D12: 0.44 | F12: =D12*Parametros!$B$5
A13: B.2) Fotografías de campaña (8 fotos finales por referencia, escalado parcial)
A14: Concepto | B14: Herramienta / Modelo IA | C14: Créditos | D14: Valor (USD) | E14: — | F14: Valor (COP)
A15: Imagen base (modelo + outfit) | B15: Figma Weave / Nanobanana Pro 4K | C15: 23 | D15: 0.23 | F15: =D15*Parametros!$B$5
A16: Set de 4 fotos adicionales (4K) | B16: Figma Weave / Nanobanana Pro 4K | C16: 92 | D16: 0.92 | F16: =D16*Parametros!$B$5
A17: Set de 4 fotos adicionales (2K) | B17: Figma Weave / Nanobanana Pro 2K | C17: 44 | D17: 0.44 | F17: =D17*Parametros!$B$5
A18: Escalado Topaz Upscaler (4 de 8 fotos) | B18: Figma Weave | C18: 76 | D18: 0.76 | F18: =D18*Parametros!$B$5
A19: Nodos LLM auxiliares para prompts (7) | B19: Figma Weave — Any LLM | C19: 7 | D19: 0.07 | F19: =D19*Parametros!$B$5
A20: Subtotal base fichas + fotografía por referencia | C20: =SUM(C11:C12)+SUM(C15:C19) | D20: =SUM(D11:D12)+SUM(D15:D19) | F20: =D20*Parametros!$B$5
A21: Contingencia por regeneración de imágenes/fichas (% Parámetros) | D21: ='Costeo Generacion IA'!$D$20*Parametros!$B$23 | F21: =D21*Parametros!$B$5
A22: Subtotal fichas + fotografía INCL. contingencia | D22: ='Costeo Generacion IA'!$D$20+'Costeo Generacion IA'!$D$21 | F22: =D22*Parametros!$B$5
A24: B.3) Video de campaña
A25: Concepto | B25: Herramienta / Modelo IA | C25: Créditos | D25: Valor (USD) | E25: — | F25: Valor (COP)
A26: Video de campaña (4 clips 1080p x 4s, Omniflash) | B26: APIMART | C26: 10 | D26: 1 | F26: =D26*Parametros!$B$5
A27: Contingencia por regeneración de clips de video (% Parámetros) | D27: ='Costeo Generacion IA'!$D$26*Parametros!$B$24 | F27: =D27*Parametros!$B$5
A28: Video INCL. contingencia | D28: ='Costeo Generacion IA'!$D$26+'Costeo Generacion IA'!$D$27 | F28: =D28*Parametros!$B$5
A30: TOTAL GENERACIÓN POR REFERENCIA (fichas + 8 fotos + video, incl. contingencia) | D30: ='Costeo Generacion IA'!$D$22+'Costeo Generacion IA'!$D$28 | F30: =D30*Parametros!$B$5
A33: C) PROYECCIÓN — COSTO TOTAL DE GENERACIÓN IA PARA LAS 55 REFERENCIAS
A34: Concepto | B34: Cantidad | D34: Valor (USD) | E34: — | F34: Valor (COP)
A35: Modelos IA (identidad, 1 vez c/u) | B35: =Parametros!$B$9 | D35: ='Costeo Generacion IA'!$D$6*Parametros!$B$9 | F35: =D35*Parametros!$B$5
A36: Fichas técnicas + fotografía (incl. contingencia) x referencia | B36: =Parametros!$B$8 | D36: ='Costeo Generacion IA'!$D$22*Parametros!$B$8 | F36: =D36*Parametros!$B$5
A37: Videos de campaña (incl. contingencia) x referencia | B37: =Parametros!$B$8 | D37: ='Costeo Generacion IA'!$D$28*Parametros!$B$8 | F37: =D37*Parametros!$B$5
A38: TOTAL COSTO DE GENERACIÓN IA (COGS) | D38: =D35+D36+D37 | F38: =D38*Parametros!$B$5

Sheet Horas Estimadas
A1: DESGLOSE SUGERIDO DE HORAS DE DIRECCIÓN CREATIVA / OPERACIÓN
A2: Referencial: copia el total en Parámetros > Horas estimadas si lo validas.
A4: Actividad | B4: Horas | C4: Nota
A5: Setup y ajuste de identidad de los 5 modelos IA | B5: 5 | C5: 1h por modelo: selección de variante, validación de consistencia
A6: Prompt engineering y curaduría por referencia (55 x 0.5h) | B6: 27.5 | C6: Ajuste de prompts de fichas, fit y fotos; selección de mejores tomas
A7: Control de calidad y consistencia de marca (55 x 0.15h) | B7: 8.25 | C7: Revisión de fidelidad de prenda, anatomía, coherencia visual
A8: Rondas de ajustes / feedback del cliente | B8: 8 | C8: Estimado 1 ronda de ajustes global + puntuales
A9: Gestión de proyecto, organización de entrega y empaquetado | B9: 6 | C9: Nomenclatura, carpetas, envío final
A10: TOTAL HORAS SUGERIDAS | B10: =SUM(B5:B9)

Sheet Resumen y Cotizacion
A1: RESUMEN DE COSTOS Y PROPUESTA DE COTIZACIÓN
A2: 55 referencias · 5 modelos IA · fichas técnicas + 8 fotos de campaña + 1 video por referencia, incl. contingencia por regeneración
A4: 1) COSTOS DIRECTOS Y DE OPERACIÓN
A5: Concepto | B5: Valor (USD) | C5: Valor (COP) | D5: Fuente / Nota
A6: Costo de generación IA (modelos + fichas + fotos + video, incl. contingencia) | B6: ='Costeo Generacion IA'!$D$38 | C6: ='Costeo Generacion IA'!$F$38 | D6: Ver hoja 'Costeo Generacion IA'
A7: Suscripciones de herramientas (parte asignada al proyecto) | B7: =(Parametros!$B$13+Parametros!$B$15+Parametros!$B$14/Parametros!$B$5)*Parametros!$B$16 | C7: =(Parametros!$B$13*Parametros!$B$5+Parametros!$B$15*Parametros!$B$5+Parametros!$B$14)*Parametros!$B$16 | D7: Claude + ChatGPT + Figma Weave, según % asignado en Parámetros
A8: Mano de obra / dirección creativa | B8: =(Parametros!$B$19*Parametros!$B$20)/Parametros!$B$5 | C8: =Parametros!$B$19*Parametros!$B$20 | D8: Horas x tarifa/hora definidas en Parámetros
A9: COSTO TOTAL DEL PROYECTO | B9: =B6+B7+B8 | C9: =C6+C7+C8
A11: 2) PRECIO DE VENTA CON MARGEN OBJETIVO (Parámetros)
A12: Concepto | B12: Valor (USD) | C12: Valor (COP) | D12: Nota
A13: Precio de venta (costo total x (1 + margen)) | B13: =B9*(1+Parametros!$B$27) | C13: =C9*(1+Parametros!$B$27)
A14: IVA (si aplica) | B14: =B13*Parametros!$B$28 | C14: =C13*Parametros!$B$28
A15: PRECIO TOTAL AL CLIENTE | B15: =B13+B14 | C15: =C13+C14
A16: Precio por referencia (promedio) | C16: =C15/Parametros!$B$8
A17: Utilidad neta estimada del proyecto | B17: =B13-B9 | C17: =C13-C9
A19: 3) ESCENARIOS DE MARGEN (referencia rápida)
A20: Margen | B20: Precio total (COP) | C20: Precio por referencia (COP) | D20: Nota
A21: 0.5 | B21: =$C$9*(1+A21)*(1+Parametros!$B$28) | C21: =B21/Parametros!$B$8 | D21: Competitivo
A22: 0.6 | B22: =$C$9*(1+A22)*(1+Parametros!$B$28) | C22: =B22/Parametros!$B$8 | D22: Estándar de agencia (recomendado / actual)
A23: 0.7 | B23: =$C$9*(1+A23)*(1+Parametros!$B$28) | C23: =B23/Parametros!$B$8 | D23: Premium / alto valor percibido

Sheet Escenario Mixto Video-Fotos
A1: APARTADO: ESCENARIO MIXTO — SOLO LA MITAD DE REFERENCIAS CON VIDEO
A2: Tipo A: 8 fotos + video · Tipo B: 5 fotos, sin video. No reemplaza el escenario base; es un apartado alternativo.
A4: 1) PARÁMETROS DEL ESCENARIO (editable)
A5: % de referencias con video (8 fotos + video) | B5: 0.5 | C5: Referencias sin video reciben solo 5 fotos, no video.
A6: N° de fotos finales para referencias SIN video | B6: 5
A7: N° de fotos finales para referencias CON video (referencia) | B7: 8
A8: Supuesto: el costo de generación fotográfica + escalado se prorratea linealmente según el número de fotos entregadas (el pipeline genera en lotes de 4). Las fichas técnicas de producto se mantienen fijas, ya que se necesitan sin importar cuántas fotos finales se entreguen.
A10: 2) DISTRIBUCIÓN DE LAS 55 REFERENCIAS
A11: Concepto | B11: Cantidad
A12: Total de referencias | B12: =Parametros!$B$8
A13: Referencias CON video (Tipo A — 8 fotos + video) | B13: =ROUND(B12*'Escenario Mixto Video-Fotos'!$B$5,0)
A14: Referencias SIN video (Tipo B — 5 fotos, sin video) | B14: =B12-B13
A16: 3) COSTO UNITARIO POR TIPO DE REFERENCIA (incl. contingencia)
A17: Concepto | B17: Tipo A — con video (8 fotos) | C17: Tipo B — sin video (5 fotos) | D17: Nota
A18: Fichas técnicas (identidad + fit interno) — fijo | B18: ='Costeo Generacion IA'!$D$11+'Costeo Generacion IA'!$D$12 | C18: ='Costeo Generacion IA'!$D$11+'Costeo Generacion IA'!$D$12 | D18: Igual para ambos tipos: se necesita la ficha sin importar el N° de fotos
A19: Fotografía + escalado (Tipo A: set completo · Tipo B: itemizado igual al escenario Sin Video) | B19: ='Costeo Generacion IA'!$D$15+'Costeo Generacion IA'!$D$16+'Costeo Generacion IA'!$D$17+'Costeo Generacion IA'!$D$19+'Costeo Generacion IA'!$D$18 | C19: ='Costeo Generacion IA'!$D$15+'Costeo Generacion IA'!$D$16+'Costeo Generacion IA'!$D$19+'Costeo Generacion IA'!$D$18 | D19: Tipo B ya no prorratea: usa imagen base + 1 set de 4 fotos (4K) + LLM + escalado de esas 4, igual que la hoja Sin Video 5 Fotos
A20: Subtotal base (fichas + fotografía) | B20: =B18+B19 | C20: =C18+C19
A21: Contingencia por regeneración de imágenes/fichas (%) | B21: =B20*Parametros!$B$23 | C21: =C20*Parametros!$B$23
A22: Video de campaña (base) | B22: ='Costeo Generacion IA'!$D$26 | C22: 0 | D22: Tipo B no incluye video
A23: Contingencia por regeneración de video (%) | B23: =B22*Parametros!$B$24 | C23: 0
A24: TOTAL POR REFERENCIA incl. contingencia (USD) | B24: =B20+B21+B22+B23 | C24: =C20+C21+C22+C23
A25: TOTAL POR REFERENCIA incl. contingencia (COP) | B25: =B24*Parametros!$B$5 | C25: =C24*Parametros!$B$5
A27: 4) COSTO TOTAL DE GENERACIÓN — PROYECTO MIXTO (55 referencias)
A28: Concepto | B28: Cantidad | C28: Valor (USD) | D28: Valor (COP)
A29: Modelos IA (identidad, 1 vez c/u) | B29: =Parametros!$B$9 | C29: ='Costeo Generacion IA'!$D$6*Parametros!$B$9 | D29: =C29*Parametros!$B$5
A30: Referencias Tipo A (con video) | B30: =B13 | C30: =B24*B13 | D30: =C30*Parametros!$B$5
A31: Referencias Tipo B (sin video, 5 fotos) | B31: =B14 | C31: =C24*B14 | D31: =C31*Parametros!$B$5
A32: TOTAL COSTO DE GENERACIÓN IA (mixto) | C32: =C29+C30+C31 | D32: =D29+D30+D31
A34: 5) COSTO TOTAL DEL PROYECTO Y PRECIO CON MARGEN
A35: Concepto | C35: Valor (USD) | D35: Valor (COP)
A36: Suscripciones de herramientas (parte asignada) | C36: =(Parametros!$B$13+Parametros!$B$15+Parametros!$B$14/Parametros!$B$5)*Parametros!$B$16 | D36: =C36*Parametros!$B$5
A37: Mano de obra / dirección creativa | C37: =(Parametros!$B$19*Parametros!$B$20)/Parametros!$B$5 | D37: =Parametros!$B$19*Parametros!$B$20
A38: COSTO TOTAL DEL PROYECTO (mixto) | C38: =C32+C36+C37 | D38: =D32+D36+D37
A39: PRECIO TOTAL AL CLIENTE (costo x (1+margen) x (1+IVA)) | C39: =C38*(1+Parametros!$B$27)*(1+Parametros!$B$28) | D39: =D38*(1+Parametros!$B$27)*(1+Parametros!$B$28)
A40: Precio por referencia (promedio del proyecto) | D40: =D39/Parametros!$B$8
A42: 6) PRECIO DE VENTA SUGERIDO POR TIPO DE REFERENCIA (lista diferenciada)
A43: Concepto | B43: Tipo A — con video (COP) | C43: Tipo B — sin video (COP) | D43: Nota
A44: Precio de venta por referencia (costo unitario x (1+margen) x (1+IVA)) | B44: =B25*(1+Parametros!$B$27)*(1+Parametros!$B$28) | C44: =C25*(1+Parametros!$B$27)*(1+Parametros!$B$28) | D44: Antes de prorratear gastos fijos (herramientas + mano de obra)
A45: Nota: esta lista por tipo aplica el margen solo sobre el costo variable de generación de cada referencia. Los costos fijos (herramientas + mano de obra) ya están cubiertos en el precio total del punto 5, que es la cifra a cotizar formalmente al cliente.

Sheet Escenario Sin Video 5 Fotos
A1: APARTADO: ESCENARIO SIN VIDEO — 5 FOTOS POR REFERENCIA
A2: De las 5 fotos entregadas, 1 es la ficha de identidad de la prenda y 4 son fotos de campaña, todas con escalado Topaz. La ficha de fit se sigue generando (uso interno) pero no se entrega ni se cuenta en las 5.
A4: 1) COMPOSICIÓN DE LAS 5 FOTOS ENTREGADAS
A5: Foto # | B5: Origen | C5: ¿Lleva escalado Topaz? | D5: Nota
A6: 1 | B6: Ficha de identidad de la prenda (KIE) | C6: No | D6: Ya se entrega en alta resolución nativa (4K)
A7: 2 | B7: Foto de campaña (Figma Weave / Nanobanana Pro) | C7: Sí
A8: 3 | B8: Foto de campaña (Figma Weave / Nanobanana Pro) | C8: Sí
A9: 4 | B9: Foto de campaña (Figma Weave / Nanobanana Pro) | C9: Sí
A10: 5 | B10: Foto de campaña (Figma Weave / Nanobanana Pro) | C10: Sí
A12: 2) COSTO UNITARIO POR REFERENCIA (incl. contingencia)
A13: Concepto | B13: Valor (USD) | C13: Valor (COP) | D13: Nota
A14: Ficha de identidad de la prenda — SE ENTREGA (foto 1 de 5) | B14: ='Costeo Generacion IA'!$D$11 | C14: =B14*Parametros!$B$5
A15: Ficha de fit — uso interno, NO se entrega ni cuenta en las 5 | B15: ='Costeo Generacion IA'!$D$12 | C15: =B15*Parametros!$B$5
A16: Imagen base (modelo + outfit) | B16: ='Costeo Generacion IA'!$D$15 | C16: =B16*Parametros!$B$5
A17: Set de 4 fotos de campaña (4K) — fotos 2 a 5 | B17: ='Costeo Generacion IA'!$D$16 | C17: =B17*Parametros!$B$5
A18: Nodos LLM auxiliares para prompts | B18: ='Costeo Generacion IA'!$D$19 | C18: =B18*Parametros!$B$5
A19: Escalado Topaz Upscaler (4 de 5 fotos: las de campaña) | B19: ='Costeo Generacion IA'!$D$18 | C19: =B19*Parametros!$B$5 | D19: Mismo costo que escalar 4 de 8 en el escenario base
A20: Subtotal base por referencia | B20: =B14+B15+B16+B17+B18+B19 | C20: =B20*Parametros!$B$5
A21: Contingencia por regeneración de fotos/fichas (% Parámetros) | B21: =B20*Parametros!$B$23 | C21: =B21*Parametros!$B$5
A22: TOTAL GENERACIÓN POR REFERENCIA incl. contingencia | B22: =B20+B21 | C22: =B22*Parametros!$B$5
A24: 3) COSTO TOTAL DE GENERACIÓN IA — PROYECTO (55 referencias)
A25: Concepto | B25: Cantidad | C25: Valor (USD) | D25: Valor (COP)
A26: Modelos IA (identidad, 1 vez c/u) | B26: =Parametros!$B$9 | C26: ='Costeo Generacion IA'!$D$6*Parametros!$B$9 | D26: =C26*Parametros!$B$5
A27: Fichas + fotografía (5 fotos, incl. contingencia) x referencia | B27: =Parametros!$B$8 | C27: =B22*Parametros!$B$8 | D27: =C27*Parametros!$B$5
A28: TOTAL COSTO DE GENERACIÓN IA (COGS) | C28: =C26+C27 | D28: =D26+D27
A30: 4) COSTO TOTAL DEL PROYECTO Y PRECIO CON MARGEN
A31: Concepto | C31: Valor (USD) | D31: Valor (COP)
A32: Suscripciones de herramientas (parte asignada) | C32: =(Parametros!$B$13+Parametros!$B$15+Parametros!$B$14/Parametros!$B$5)*Parametros!$B$16 | D32: =C32*Parametros!$B$5
A33: Mano de obra / dirección creativa (mismas horas del escenario base — ajustable) | C33: =(Parametros!$B$19*Parametros!$B$20)/Parametros!$B$5 | D33: =Parametros!$B$19*Parametros!$B$20
A34: COSTO TOTAL DEL PROYECTO (sin video, 5 fotos) | C34: =C28+C32+C33 | D34: =D28+D32+D33
A35: PRECIO TOTAL AL CLIENTE (costo x (1+margen) x (1+IVA)) | C35: =C34*(1+Parametros!$B$27)*(1+Parametros!$B$28) | D35: =D34*(1+Parametros!$B$27)*(1+Parametros!$B$28)
A36: Precio por referencia | D36: =D35/Parametros!$B$8
A37: Utilidad neta estimada del proyecto | C37: =C35-C34 | D37: =D35-D34
A39: 5) COMPARATIVA vs. ESCENARIO BASE (8 fotos + video)
A40: Concepto | B40: Escenario base (8 fotos+video) | C40: Este escenario (5 fotos, sin video) | D40: Diferencia
A41: Precio por referencia | B41: ='Resumen y Cotizacion'!$C$16 | C41: =D36 | D41: =C41-B41

Sheet Opcion B - 6 Fotos
A1: APARTADO: OPCION B — 7 FOTOS (1 FICHA + 6 CAMPAÑA) + VIDEO
A2: Desglose explicito de las 6 fotografias de campana: 3 generadas nativas en 4K y 3 generadas nativas en 2K, con escalado Topaz aplicado al 100% (las 6), siguiendo el mismo criterio del escenario "Sin Video 5 Fotos".
A4: 1) COMPOSICION DE LAS 7 FOTOS ENTREGADAS
A5: Foto # | B5: Origen | C5: Lleva escalado Topaz? | D5: Nota
A6: 1 | B6: Ficha de identidad de la prenda (KIE) | C6: No | D6: Ya se entrega en alta resolucion nativa (4K)
A7: 2 | B7: Foto de campana - generada nativa en 4K (Figma Weave / Nanobanana Pro) | C7: Si
A8: 3 | B8: Foto de campana - generada nativa en 4K (Figma Weave / Nanobanana Pro) | C8: Si
A9: 4 | B9: Foto de campana - generada nativa en 4K (Figma Weave / Nanobanana Pro) | C9: Si
A10: 5 | B10: Foto de campana - generada nativa en 2K (Figma Weave / Nanobanana Pro) | C10: Si
A11: 6 | B11: Foto de campana - generada nativa en 2K (Figma Weave / Nanobanana Pro) | C11: Si
A12: 7 | B12: Foto de campana - generada nativa en 2K (Figma Weave / Nanobanana Pro) | C12: Si
A14: 2) COSTO UNITARIO POR REFERENCIA (incl. contingencia)
A15: Concepto | B15: Valor (USD) | C15: Valor (COP) | D15: Nota
A16: Ficha de identidad de la prenda - SE ENTREGA (foto 1 de 7) | B16: 0.72 | C16: 2376
A17: Ficha de fit - uso interno, NO se entrega ni cuenta en las 7 | B17: 0.44 | C17: 1452
A18: Imagen base (modelo + outfit) | B18: 0.23 | C18: 759 | D18: Preparacion; no es una foto final entregada
A19: 3 fotos de campana nativas en 4K (759 c/u) | B19: 0.69 | C19: 2277 | D19: Fotos 2 a 4
A20: 3 fotos de campana nativas en 2K (363 c/u) | B20: 0.33 | C20: 1089 | D20: Fotos 5 a 7
A21: Nodos LLM auxiliares para prompts | B21: 0.07 | C21: 231
A22: Escalado Topaz Upscaler (6 de 6 fotos de campana - el 100%) | B22: 1.14 | C22: 3762 | D22: 627 COP por foto, aplicado a las 6 fotos de campana
A23: Subtotal base por referencia | B23: 3.62 | C23: 11946
A24: Contingencia por regeneracion de fotos/fichas (% Parametros) | B24: 0.724 | C24: 2389.2
A25: Subtotal fichas + fotografia INCL. contingencia | B25: 4.344 | C25: 14335.2
A27: 3) VIDEO DE CAMPANA
A28: Concepto | B28: Valor (USD) | C28: Valor (COP) | D28: Nota
A29: Video de campana (4 clips 1080p x 4s, Omniflash) | B29: 1 | C29: 3300 | D29: APIMART - igual que en las demas opciones
A30: Contingencia por regeneracion de clips de video (% Parametros) | B30: 0.25 | C30: 825
A31: Video INCL. contingencia | B31: 1.25 | C31: 4125
A33: 4) TOTAL GENERACION POR REFERENCIA (Opcion B) incl. contingencia
A34: Concepto | B34: Valor (USD) | C34: Valor (COP) | D34: Nota
A35: TOTAL POR REFERENCIA incl. contingencia (fichas + 7 fotos + video) | B35: 5.594 | C35: 18460.2
A37: 5) COSTO TOTAL DE GENERACION IA - PROYECTO (55 referencias)
A38: Concepto | B38: Cantidad | C38: Valor (USD) | D38: Valor (COP)
A39: Modelos IA (identidad, 1 vez c/u) | B39: 5 | C39: 3.3 | D39: 10890
A40: Fichas + fotografia + video (incl. contingencia) x referencia | B40: 55 | C40: 307.67 | D40: 1015311
A41: TOTAL COSTO DE GENERACION IA (COGS) | C41: 310.97 | D41: 1026201
A43: 6) COSTO TOTAL DEL PROYECTO Y PRECIO CON MARGEN
A44: Concepto | C44: Valor (USD) | D44: Valor (COP)
A45: Suscripciones de herramientas (parte asignada) | C45: 50.06 | D45: 165200
A46: Mano de obra / direccion creativa | C46: 416.67 | D46: 1375000
...
